Workbook

Sheet gelONE-XE
A1: Price List 2025
B2: gelONE Gel Documentation System with in built touch screen
B3: The gelONE-XE is the ultimate in simplicity, with automated acquisition through an intuitive touch screen interface.Compatible with both traditional DNA stains and safe stains, the gelONE is suitable for any lab. The 20 x 24 cm imaging area means even large gels can be imaged with ease. Images are captured using the built in software, and saved direct to USB memory stocks for transfer to PC. The geneQUANT advanced image analysis package is included with all systems license free.
A5: Complete Systems | B5: All systems include geneQUANT analysis software license free
A6: Code | B6: 2025 Price | C6: Description
A7: GELONE-XE | B7: =INDEX('Raw Data for ERP Import'!$B:$B,MATCH(A7,'Raw Data for ERP Import'!$A:$A,0)) -> 7963 | C7: gelONE-XE with large UVT, 230V, 50Hz, Europe
A8: GELONE-XE-E60 | B8: =INDEX('Raw Data for ERP Import'!$B:$B,MATCH(A8,'Raw Data for ERP Import'!$A:$A,0)) -> 7963 | C8: gelONE-XE with large UVT, 230V, 60Hz, Europe
A9: GELONE-XE-A | B9: =INDEX('Raw Data for ERP Import'!$B:$B,MATCH(A9,'Raw Data for ERP Import'!$A:$A,0)) -> 7963 | C9: gelONE-XE with large UVT, 115V, 60Hz, USA
A11: GELONE-E | B11: =INDEX('Raw Data for ERP Import'!$B:$B,MATCH(A11,'Raw Data for ERP Import'!$A:$A,0)) -> 0 | C11: gelONE with large UVT, 230V, 50Hz, Europe
A12: GELONE-E60 | B12: =INDEX('Raw Data for ERP Import'!$B:$B,MATCH(A12,'Raw Data for ERP Import'!$A:$A,0)) -> 0 | C12: gelONE with large UVT, 230V, 60Hz, Europe
A13: GELONE-A | B13: =INDEX('Raw Data for ERP Import'!$B:$B,MATCH(A13,'Raw Data for ERP Import'!$A:$A,0)) -> 0 | C13: gelONE with large UVT, 115V, 60Hz, USA
A15: GELONE-PLUS | B15: =INDEX('Raw Data for ERP Import'!$B:$B,MATCH(A15,'Raw Data for ERP Import'!$A:$A,0)) -> 0 | C15: gelONE+ with large UVT, 230V, 50Hz, Europe
A16: GELONE-PLUS-E60 | B16: =INDEX('Raw Data for ERP Import'!$B:$B,MATCH(A16,'Raw Data for ERP Import'!$A:$A,0)) -> 0 | C16: gelONE+ with large UVT, 230V, 60Hz, Europe
A17: GELONE-PLUS-A | B17: =INDEX('Raw Data for ERP Import'!$B:$B,MATCH(A17,'Raw Data for ERP Import'!$A:$A,0)) -> 0 | C17: gelONE+ with large UVT, 115V, 60Hz, USA
A19: Options
A20: Code | C20: Description
A21: CS-FSP58 | B21: =INDEX('Raw Data for ERP Import'!$B:$B,MATCH(A21,'Raw Data for ERP Import'!$A:$A,0)) -> 603.50714 | C21: Short pass [515 -599nm] (SW032)
A22: CS-FSG-58 | B22: =INDEX('Raw Data for ERP Import'!$B:$B,MATCH(A22,'Raw Data for ERP Import'!$A:$A,0)) -> 103.1373 | C22: Safe stain filter to work with blue light converter (gelLITE/gelONE)
A23: WLC-3023 | B23: =INDEX('Raw Data for ERP Import'!$B:$B,MATCH(A23,'Raw Data for ERP Import'!$A:$A,0)) -> 155.12683 | C23: Visible light converter
A24: BLC-2126 | B24: =INDEX('Raw Data for ERP Import'!$B:$B,MATCH(A24,'Raw Data for ERP Import'!$A:$A,0)) -> 454.75538 | C24: UV to Blue Light converter, Size 21x26cm, suitable for safe dyes
A25: CS-XS-NFS | B25: =INDEX('Raw Data for ERP Import'!$B:$B,MATCH(A25,'Raw Data for ERP Import'!$A:$A,0)) -> 28.89 | C25: Neutral field screens for UV neutral fielding (1 blue, 1 frosted).
A26: CSL-PRINTUSB | C26: Mitsubishi Digital Thermal Printer | E26: Discontinued
A27: GELONE-NETUSB | B27: =INDEX('Raw Data for ERP Import'!$B:$B,MATCH(A27,'Raw Data for ERP Import'!$A:$A,0)) -> 210.37749 | C27: Network dongle
A28: UVSHIELD2020 | B28: =INDEX('Raw Data for ERP Import'!$B:$B,MATCH(A28,'Raw Data for ERP Import'!$A:$A,0)) -> 57.63555 | C28: UV Blocking Shield for gelLITE and gelONE
A29: CSL-PRINTER | B29: 1235 | C29: Sony Digital Thermal Printer
A31: Spares
A32: Code | C32: Description
A33: GELONEXE-BASE | B33: =INDEX('Raw Data for ERP Import'!$B:$B,MATCH(A33,'Raw Data for ERP Import'!$A:$A,0)) -> #N/A | C33: gelONE-XE BASE ONLY 230V, 50Hz, Europe - Other Voltages are available
A34: GELONE-BASE | B34: =INDEX('Raw Data for ERP Import'!$B:$B,MATCH(A34,'Raw Data for ERP Import'!$A:$A,0)) -> 0 | C34: gelONE Base unit without UVT
A35: CS-2020M-E | B35: =INDEX('Raw Data for ERP Import'!$B:$B,MATCH(A35,'Raw Data for ERP Import'!$A:$A,0)) -> 853.15781 | C35: Transilluminator (20 x 20cm; 302nm) 230V, 50Hz with runners | D35: Other Voltages are available
A36: CS-2024M-E | B36: =INDEX('Raw Data for ERP Import'!$B:$B,MATCH(A36,'Raw Data for ERP Import'!$A:$A,0)) -> 1057.6051 | C36: Transilluminator (20 x 24cm; 302nm) 230V, 50Hz with runners
A37: CS-MATTP | B37: =INDEX('Raw Data for ERP Import'!$B:$B,MATCH(A37,'Raw Data for ERP Import'!$A:$A,0)) -> 27.625327 | C37: Thermal paper, Matt, 1 roll
A38: CS-GLOSSP | B38: =INDEX('Raw Data for ERP Import'!$B:$B,MATCH(A38,'Raw Data for ERP Import'!$A:$A,0)) -> 27.625327 | C38: Thermal paper, Glossy, 1 roll
A39: CS-T8-254 | B39: =INDEX('Raw Data for ERP Import'!$B:$B,MATCH(A39,'Raw Data for ERP Import'!$A:$A,0)) -> 27.05157 | C39: Short wave tube, 8W, 254nm
A40: CS-T8-302 | B40: =INDEX('Raw Data for ERP Import'!$B:$B,MATCH(A40,'Raw Data for ERP Import'!$A:$A,0)) -> 33.816588 | C40: Medium wave, 8W, 302nm
A41: CS-T8-365 | B41: =INDEX('Raw Data for ERP Import'!$B:$B,MATCH(A41,'Raw Data for ERP Import'!$A:$A,0)) -> 27.593451 | C41: Longwave 8W, 365nm
A42: CS-UPP-100HD | B42: 17.55 | C42: Matt Paper roll for use with Sony printer Pk1
A43: CS-UPP-110HG | B43: 17.55 | C43: Gloss Paper roll for use with Sont printer Pk1

Sheet gelLITE
B2: gelLITE Entry Level gel Documentation System
B3: The gelLITE completes our range of gel and chemiluminescence documentation systems with an economical and effective solution for agarose gel imaging. The manually controlled camera zoom and focus gives users complete control of their imaging, and intuitive genePIX acquisition software enable a fast and efficient workflow.
A5: Complete Systems | B5: Include Darkroom, Camera, UV Transilluminator and specificed converter screens. All systems include UV emission filter. Systems including blue light converters (BLC) also include relevant emission filters. All systems include aquistion and analsys software license free.
A7: Code | B7: 2025 Price | C7: Description
A8: gelLITE | B8: =INDEX('Raw Data for ERP Import'!$B:$B,MATCH(A8,'Raw Data for ERP Import'!$A:$A,0)) -> 4170.9938 | C8: gelLITE System with UVT, 230V/50Hz, Europe
A9: gelLITESAFE | B9: =INDEX('Raw Data for ERP Import'!$B:$B,MATCH(A9,'Raw Data for ERP Import'!$A:$A,0)) -> 4626.0113 | C9: gelLITE System with UVT, BLC, 230V/50Hz, Europe
A10: gelLITEPRO | B10: =INDEX('Raw Data for ERP Import'!$B:$B,MATCH(A10,'Raw Data for ERP Import'!$A:$A,0)) -> 4436.4206 | C10: gelLITE System with UVT, WLC, 230V/50Hz, Europe
A11: gelLITEPROSAFE | B11: =INDEX('Raw Data for ERP Import'!$B:$B,MATCH(A11,'Raw Data for ERP Import'!$A:$A,0)) -> 4747.3493 | C11: gelLITE System with UVT, WLC, BLC, 230V/50Hz, Europe
A13: gelLITE-E60 | B13: =INDEX('Raw Data for ERP Import'!$B:$B,MATCH(A13,'Raw Data for ERP Import'!$A:$A,0)) -> 4170.9938 | C13: gelLITE System with UVT, 230V/60Hz, Europe
A14: gelLITESAFE-E60 | B14: =INDEX('Raw Data for ERP Import'!$B:$B,MATCH(A14,'Raw Data for ERP Import'!$A:$A,0)) -> 4626.0113 | C14: gelLITE System with UVT, BLC, 230V/60Hz, Europe
A15: gelLITEPRO-E60 | B15: =INDEX('Raw Data for ERP Import'!$B:$B,MATCH(A15,'Raw Data for ERP Import'!$A:$A,0)) -> 4436.4206 | C15: gelLITE System with UVT, WLC, 230V/60Hz, Europe
A16: gelLITEPROSAFE-E60 | B16: =INDEX('Raw Data for ERP Import'!$B:$B,MATCH(A16,'Raw Data for ERP Import'!$A:$A,0)) -> 4747.3493 | C16: gelLITE System with UVT, WLC, BLC, 230V/60Hz, Europe
A18: gelLITE-A | B18: =INDEX('Raw Data for ERP Import'!$B:$B,MATCH(A18,'Raw Data for ERP Import'!$A:$A,0)) -> 4170.9938 | C18: gelLITE System with UVT, 115V/60Hz, USA
A19: gelLITESAFE-A | B19: =INDEX('Raw Data for ERP Import'!$B:$B,MATCH(A19,'Raw Data for ERP Import'!$A:$A,0)) -> 4626.0113 | C19: gelLITE System with UVT, BLC, 115V/60Hz, USA
A20: gelLITEPRO-A | B20: =INDEX('Raw Data for ERP Import'!$B:$B,MATCH(A20,'Raw Data for ERP Import'!$A:$A,0)) -> 4436.4206 | C20: gelLITE System with UVT, WLC, 115V/60Hz, USA
A21: gelLITEPROSAFE-A | B21: =INDEX('Raw Data for ERP Import'!$B:$B,MATCH(A21,'Raw Data for ERP Import'!$A:$A,0)) -> 4747.3493 | C21: gelLITE System with UVT, WLC, BLC, 115V/60Hz, USA
A23: Options
A24: Code | C24: Description
A25: CS-FSP58 | B25: =INDEX('Raw Data for ERP Import'!$B:$B,MATCH(A25,'Raw Data for ERP Import'!$A:$A,0)) -> 603.50714 | C25: Short pass filter (SW032)
A26: CS-FSG-58 | B26: =INDEX('Raw Data for ERP Import'!$B:$B,MATCH(A26,'Raw Data for ERP Import'!$A:$A,0)) -> 103.1373 | C26: Safe stain filter to work with blue light converter (gelLITE/gelONE)
A27: WLC-3023 | B27: =INDEX('Raw Data for ERP Import'!$B:$B,MATCH(A27,'Raw Data for ERP Import'!$A:$A,0)) -> 155.12683 | C27: Visible light converter
A28: CS-ULTRA-SLIM-LED | B28: =INDEX('Raw Data for ERP Import'!$B:$B,MATCH(A28,'Raw Data for ERP Import'!$A:$A,0)) -> 811.7596 | C28: Blue slimline LED transilluminator, 10x12cm + sliding tray
A29: BLC-2126 | B29: =INDEX('Raw Data for ERP Import'!$B:$B,MATCH(A29,'Raw Data for ERP Import'!$A:$A,0)) -> 454.75538 | C29: UV to Blue Light converter, Size 21x26cm, suitable for safe dyes
A30: CS-XS-NFS | B30: =INDEX('Raw Data for ERP Import'!$B:$B,MATCH(A30,'Raw Data for ERP Import'!$A:$A,0)) -> 28.89 | C30: Neutral field screens for UV neutral fielding (1 blue, 1 frosted).
A31: CSL-PRINTUSB | C31: Mitsubishi Digital Thermal Printer | E31: discontinued
A32: UVSHIELD2020 | B32: =INDEX('Raw Data for ERP Import'!$B:$B,MATCH(A32,'Raw Data for ERP Import'!$A:$A,0)) -> 57.63555 | C32: UV Blocking Shield for gelLITE and gelONE
A33: CSL-PRINTER | B33: 1235 | C33: Sony Digital Thermal Printer
A34: LAPTOP | B34: 975 | C34: Laptop for genePIX - Contact Thsitle for latest specification
A36: Spares
A37: Code | C37: Description
A38: GELLITE-IG3 | B38: =INDEX('Raw Data for ERP Import'!$B:$B,MATCH(A38,'Raw Data for ERP Import'!$A:$A,0)) -> 4174.7856 | C38: gelLITE, 3MP 12/16bit system, With epi LED white lights, filter drawer & UV filter. | D38: Other Voltages are available
A39: CS-2020M-E | B39: =INDEX('Raw Data for ERP Import'!$B:$B,MATCH(A39,'Raw Data for ERP Import'!$A:$A,0)) -> 853.15781 | C39: Transilluminator (20 x 20cm; 302nm) 230V, 50Hz with runners
A40: CS-MATTP | B40: =INDEX('Raw Data for ERP Import'!$B:$B,MATCH(A40,'Raw Data for ERP Import'!$A:$A,0)) -> 27.625327 | C40: Thermal paper, Matt, 1 roll
A41: CS-GLOSSP | B41: =INDEX('Raw Data for ERP Import'!$B:$B,MATCH(A41,'Raw Data for ERP Import'!$A:$A,0)) -> 27.625327 | C41: Thermal paper, Glossy, 1 roll
A42: CS-T8-254 | B42: =INDEX('Raw Data for ERP Import'!$B:$B,MATCH(A42,'Raw Data for ERP Import'!$A:$A,0)) -> 27.05157 | C42: Short wave tube, 8W, 254nm
A43: CS-T8-302 | B43: =INDEX('Raw Data for ERP Import'!$B:$B,MATCH(A43,'Raw Data for ERP Import'!$A:$A,0)) -> 33.816588 | C43: Medium wave, 8W, 302nm
A44: CS-T8-365 | B44: =INDEX('Raw Data for ERP Import'!$B:$B,MATCH(A44,'Raw Data for ERP Import'!$A:$A,0)) -> 27.593451 | C44: Longwave 8W, 365nm
A45: CS-UPP-100HD | B45: 17.55 | C45: Matt Paper roll for use with Sony printer Pk1
A46: CS-UPP-110HG | B46: 17.55 | C46: Gloss Paper roll for use with Sont printer Pk1

Sheet gelPRO
D2: gelPRO Gel Documentation System
D3: gelPRO has a high resolution 5m pixel camera which is capable of giving outstanding images with incredible spatial resolution. The gelPRO gel documentation system has a stylish modular design and includes a motor driven zoom lens as standard, as well as a motor driven filter wheel. Internal lighting comes from a UV transilluminator or a blue light LED module to further extend the applications possible with the gelPRO. This system can be upgraded to a chemiluminescence imager.
A5: Complete Systems | B5: Include Darkroom, Camera, UV Transilluminator. All systems include UV emission filter. All systems include aquistion and analsys software license free.
A6: Code | B6: 2025 Price | C6: Description
A7: gelPRO-302E | B7: =INDEX('Raw Data for ERP Import'!$B:$B,MATCH(A7,'Raw Data for ERP Import'!$A:$A,0)) -> 9372.0576 | C7: gelPRO with Large 302nm 230V 50Hz (Europe) UVT
A8: gelPRO-302SK | B8: =INDEX('Raw Data for ERP Import'!$B:$B,MATCH(A8,'Raw Data for ERP Import'!$A:$A,0)) -> 9372.0576 | C8: gelPRO with Large 302nm 220V 60Hz (S.Korea, S Arabia) UVT
A9: gelPRO-302USA | B9: =INDEX('Raw Data for ERP Import'!$B:$B,MATCH(A9,'Raw Data for ERP Import'!$A:$A,0)) -> 9372.0576 | C9: gelPRO with Large 302nm 115V 60Hz (USA) UVT
A10: gelPRO-302C | B10: =INDEX('Raw Data for ERP Import'!$B:$B,MATCH(A10,'Raw Data for ERP Import'!$A:$A,0)) -> 9372.0576 | C10: gelPRO with Large 302nm 115V 60Hz (Canada) UVT
A11: gelPRO-302J | B11: =INDEX('Raw Data for ERP Import'!$B:$B,MATCH(A11,'Raw Data for ERP Import'!$A:$A,0)) -> 9372.0576 | C11: gelPRO with Large 302nm 100V 50/60Hz (Japan) UVT
A13: Options
A14: Code | C14: Description
A15: GX-VP | B15: =INDEX('Raw Data for ERP Import'!$B:$B,MATCH(A15,'Raw Data for ERP Import'!$A:$A,0)) -> 131.75156 | C15: Viewing platform
A16: CS-ULTRA-BRIGHT-LED | B16: =INDEX('Raw Data for ERP Import'!$B:$B,MATCH(A16,'Raw Data for ERP Import'!$A:$A,0)) -> 1132.659 | C16: Blue LED Transilluminator, Viewing area 20x16cm + sliding tray
A17: CS-BLC | B17: =INDEX('Raw Data for ERP Import'!$B:$B,MATCH(A17,'Raw Data for ERP Import'!$A:$A,0)) -> 476.00563 | C17: UV to Blue light converter, Size 25x30cm suitable for DNA safe dyes
A18: CS-FSG-72 | B18: =INDEX('Raw Data for ERP Import'!$B:$B,MATCH(A18,'Raw Data for ERP Import'!$A:$A,0)) -> 128.92163 | C18: Safe stain filter to work with blue light converter (gelPRO/chemiPRO)
A19: CS-WLPAD | B19: =INDEX('Raw Data for ERP Import'!$B:$B,MATCH(A19,'Raw Data for ERP Import'!$A:$A,0)) -> 565.25669 | C19: 20 x 14 cm Fold down white light pad with brackets
A20: CS-WLC | B20: =INDEX('Raw Data for ERP Import'!$B:$B,MATCH(A20,'Raw Data for ERP Import'!$A:$A,0)) -> 155.12683 | C20: Viisible light converter, Size 30.5x33cm
A21: CS-EPIUV | B21: =INDEX('Raw Data for ERP Import'!$B:$B,MATCH(A21,'Raw Data for ERP Import'!$A:$A,0)) -> 1300.5154 | C21: 2 x UV module – with 302nm tubes
A22: CS-FSP72 | B22: =INDEX('Raw Data for ERP Import'!$B:$B,MATCH(A22,'Raw Data for ERP Import'!$A:$A,0)) -> 622.63236 | C22: Short pass [515 -599nm] (SW032)
A23: CS-NFS | B23: =INDEX('Raw Data for ERP Import'!$B:$B,MATCH(A23,'Raw Data for ERP Import'!$A:$A,0)) -> 28.89 | C23: Neutral field screens for UV neutral fielding (1 blue, 1 frosted).
A24: CSL-PRINTUSB | C24: Mitsubishi Digital Thermal Printer | E24: discontinued
A25: UVSHIELD2530 | B25: =INDEX('Raw Data for ERP Import'!$B:$B,MATCH(A25,'Raw Data for ERP Import'!$A:$A,0)) -> 68.252625 | C25: UV Blocking Shield for gelPRO and chemiPRO
A26: CSL-PRINTER | B26: 1235 | C26: Sony Digital Thermal Printer
A27: LAPTOP | B27: 975 | C27: Laptop for genePIX - Contact Thsitle for latest specification
A29: Spares
A30: Code | C30: Description
A31: CS-DARKROOM | B31: =INDEX('Raw Data for ERP Import'!$B:$B,MATCH(A31,'Raw Data for ERP Import'!$A:$A,0)) -> 5308.5375 | C31: chemiPRO/gelPRO Base System
A32: CS-CAM-GELPRO | B32: =INDEX('Raw Data for ERP Import'!$B:$B,MATCH(A32,'Raw Data for ERP Import'!$A:$A,0)) -> 2939.5493 | C32: gelPRO Camera/Lens | D32: Other Voltages are available
A33: CS-2020M-E | B33: =INDEX('Raw Data for ERP Import'!$B:$B,MATCH(A33,'Raw Data for ERP Import'!$A:$A,0)) -> 853.15781 | C33: Transilluminator (20x20cm; 302nm) 230V, 50Hz + runners | D33: Other Voltages are available
A34: CS-2530M-E | B34: =INDEX('Raw Data for ERP Import'!$B:$B,MATCH(A34,'Raw Data for ERP Import'!$A:$A,0)) -> 1509.1414 | C34: Transilluminator (25x30cm; 302nm) 230V, 50Hz + runners | D34: Other Voltages are available
A35: CS-2020LM-E | B35: =INDEX('Raw Data for ERP Import'!$B:$B,MATCH(A35,'Raw Data for ERP Import'!$A:$A,0)) -> 1183.0455 | C35: Transilluminator (20x20cm; 302/365nm) 230V, 50Hz + runners | D35: Other Voltages are available
A36: CS-2530LM-E | B36: =INDEX('Raw Data for ERP Import'!$B:$B,MATCH(A36,'Raw Data for ERP Import'!$A:$A,0)) -> 1677.877 | C36: Transilluminator (25x30cm; 302/365nm) 230V, 50Hz + runners
A37: CS-MATTP | B37: =INDEX('Raw Data for ERP Import'!$B:$B,MATCH(A37,'Raw Data for ERP Import'!$A:$A,0)) -> 27.625327 | C37: Thermal paper, Matt, 1 roll
A38: CS-GLOSSP | B38: =INDEX('Raw Data for ERP Import'!$B:$B,MATCH(A38,'Raw Data for ERP Import'!$A:$A,0)) -> 27.625327 | C38: Thermal paper, Glossy, 1 roll
A39: CS-T8-254 | B39: =INDEX('Raw Data for ERP Import'!$B:$B,MATCH(A39,'Raw Data for ERP Import'!$A:$A,0)) -> 27.05157 | C39: Shortwave tube, 8W, 254nm
A40: CS-T8-302 | B40: =INDEX('Raw Data for ERP Import'!$B:$B,MATCH(A40,'Raw Data for ERP Import'!$A:$A,0)) -> 33.816588 | C40: Mediumwave, 8W, 302nm
A41: CS-T8-365 | B41: =INDEX('Raw Data for ERP Import'!$B:$B,MATCH(A41,'Raw Data for ERP Import'!$A:$A,0)) -> 27.593451 | C41: Longwave 8W, 365nm
A42: CS-UPP-100HD | B42: 17.55 | C42: Matt Paper roll for use with Sony printer Pk1
A43: CS-UPP-110HG | B43: 17.55 | C43: Gloss Paper roll for use with Sont printer Pk1

Sheet chemLITE
E2: chemiLITE Chemiluminescence Imaging System
E3: The chemiLITE is our entry level chemiluminescence documentation system. Designed for imaging any chemiluminescence substrate and as a direct replacement for X-ray film, it is capable of picogram or femtogram protein level detection. The compactness of this system makes it perfect for labs looking to set up chemiluminescnce imaging, without the need to accomodate a large, multifuction system.
A5: Complete System | B5: Includes Imaging system and Aqusition and Analysis softare license free
A6: Code | B6: 2025 Price | C6: Description
A7: ChemiLITE | B7: =INDEX('Raw Data for ERP Import'!$B:$B,MATCH(A7,'Raw Data for ERP Import'!$A:$A,0)) -> 10775.466 | C7: Dedicated High Performance, compact Chemi System
A9: Options
A10: Code | C10: Description
A11: CSL-PRINTUSB | C11: Mitsubishi Digital Thermal Printer | F11: Discontinued
A12: CSL-PRINTER | B12: 1235 | C12: Sony Digital Thermal Printer
A13: LAPTOP | B13: 975 | C13: Laptop for genePIX - Contact Thsitle for latest specification
A15: Spares
A16: Code | C16: Description
A17: CS-MATTP | B17: =INDEX('Raw Data for ERP Import'!$B:$B,MATCH(A17,'Raw Data for ERP Import'!$A:$A,0)) -> 27.625327 | C17: Thermal paper, Matt, 1 roll
A18: CS-GLOSSP | B18: =INDEX('Raw Data for ERP Import'!$B:$B,MATCH(A18,'Raw Data for ERP Import'!$A:$A,0)) -> 27.625327 | C18: Thermal paper, Glossy, 1 roll
A19: CS-UPP-100HD | B19: 17.55 | C19: Matt Paper roll for use with Sony printer Pk1
A20: CS-UPP-110HG | B20: 17.55 | C20: Gloss Paper roll for use with Sont printer Pk1

Sheet chemiPRO
D2: chemiPRO Chemiluminescence Imaging System
D3: The chemiPRO is our complete solution for chemiluminescence and fluorescent western blot imaging.Featuring a highly sensitive cooled CCD Camera with high quantam efficiency, for detection of picogram level proteins, this system can image both conventional ECL style chemiluminscence blots and fluorescently tagged proteins of antibodies with the optional fluorescence module.
A5: Complete Systems | B5: Include Darkroom, Camera and Transilluminator where indicated (UVT). All systems include UV emission filter. All systems include aquistion and analsys software license free.
A6: Code | B6: 2025 Price | C6: Description
A7: ChemiPRO | B7: =INDEX('Raw Data for ERP Import'!$B:$B,MATCH(A7,'Raw Data for ERP Import'!$A:$A,0)) -> 13903.818 | C7: ChemiPRO complete system (Chemi Only, No UVT)
A8: ChemiPRO-302E | B8: =INDEX('Raw Data for ERP Import'!$B:$B,MATCH(A8,'Raw Data for ERP Import'!$A:$A,0)) -> 15242.646 | C8: ChemiPRO with 302nm 230V 50Hz (Europe) UVT
A9: chemiPRO-302SK | B9: =INDEX('Raw Data for ERP Import'!$B:$B,MATCH(A9,'Raw Data for ERP Import'!$A:$A,0)) -> 15242.646 | C9: chemiPRO with 302nm 220V 60Hz (S.Korea, S Arabia) UVT
A10: chemiPRO-302USA | B10: =INDEX('Raw Data for ERP Import'!$B:$B,MATCH(A10,'Raw Data for ERP Import'!$A:$A,0)) -> 15242.646 | C10: chemiPRO with 302nm 115V 60Hz (USA) UVT
A11: chemiPRO-302C | B11: =INDEX('Raw Data for ERP Import'!$B:$B,MATCH(A11,'Raw Data for ERP Import'!$A:$A,0)) -> 15242.646 | C11: chemiPRO with 302nm 115V 60Hz (Canada) UVT
A12: chemiPRO-302J | B12: =INDEX('Raw Data for ERP Import'!$B:$B,MATCH(A12,'Raw Data for ERP Import'!$A:$A,0)) -> 15242.646 | C12: chemiPRO with 302nm 100V 50/60Hz (Japan) UVT
A14: Options
A15: Code | C15: Description
A16: GX-VP | B16: =INDEX('Raw Data for ERP Import'!$B:$B,MATCH(A16,'Raw Data for ERP Import'!$A:$A,0)) -> 131.75156 | C16: Viewing platform
A17: CS-ULTRA-BRIGHT-LED | B17: =INDEX('Raw Data for ERP Import'!$B:$B,MATCH(A17,'Raw Data for ERP Import'!$A:$A,0)) -> 1132.659 | C17: Blue LED Transilluminator, Viewing area 20x16cm + sliding tray
A18: CS-BLC | B18: =INDEX('Raw Data for ERP Import'!$B:$B,MATCH(A18,'Raw Data for ERP Import'!$A:$A,0)) -> 476.00563 | C18: UV to Blue light converter, Size 25x30cm suitable for DNA safe dyes
A19: CS-FSG-72 | B19: =INDEX('Raw Data for ERP Import'!$B:$B,MATCH(A19,'Raw Data for ERP Import'!$A:$A,0)) -> 128.92163 | C19: Safe stain filter to work with blue light converter (gelPRO/chemiPRO)
A20: CS-WLC | B20: =INDEX('Raw Data for ERP Import'!$B:$B,MATCH(A20,'Raw Data for ERP Import'!$A:$A,0)) -> 155.12683 | C20: Viisible light converter, Size 30.5x33cm
A21: CS-EPIUV | B21: =INDEX('Raw Data for ERP Import'!$B:$B,MATCH(A21,'Raw Data for ERP Import'!$A:$A,0)) -> 1300.5154 | C21: 2 x UV module – with 302nm tubes
A22: CS-FSP | B22: =INDEX('Raw Data for ERP Import'!$B:$B,MATCH(A22,'Raw Data for ERP Import'!$A:$A,0)) -> 1096.513 | C22: Short pass [516 - 600nm] (SW06)
A23: CS-FIR | B23: =INDEX('Raw Data for ERP Import'!$B:$B,MATCH(A23,'Raw Data for ERP Import'!$A:$A,0)) -> 1776.4642 | C23: Filter for Licor multiplexing 800nm
A24: CS-FBL | B24: =INDEX('Raw Data for ERP Import'!$B:$B,MATCH(A24,'Raw Data for ERP Import'!$A:$A,0)) -> 1296.7999 | C24: 525nm Filter (range 516-539m)
A25: CS-FGL | B25: =INDEX('Raw Data for ERP Import'!$B:$B,MATCH(A25,'Raw Data for ERP Import'!$A:$A,0)) -> 1738.546 | C25: 605nm Filter for Multiplexing (range 594-610nm)
A26: CS-FRL | B26: =INDEX('Raw Data for ERP Import'!$B:$B,MATCH(A26,'Raw Data for ERP Import'!$A:$A,0)) -> 1738.546 | C26: 705nm Filter for Multiplexing (range 700-720nm)
A27: CS-FFR | B27: 1861.6 | C27: 700nm Filter for Far Red multiplexing (range 698-764nm)
A28: CHEMIMOD-RGB | B28: =INDEX('Raw Data for ERP Import'!$B:$B,MATCH(A28,'Raw Data for ERP Import'!$A:$A,0)) -> 5107.05 | C28: chemiPRO RGB Lighting Module
A29: CHEMIMOD-RGBIR | B29: =INDEX('Raw Data for ERP Import'!$B:$B,MATCH(A29,'Raw Data for ERP Import'!$A:$A,0)) -> 6609.1292 | C29: chemiPRO RGB & IR Lighitng Module
A30: CHEMIMOD-RGBIRFR | B30: =INDEX('Raw Data for ERP Import'!$B:$B,MATCH(A30,'Raw Data for ERP Import'!$A:$A,0)) -> 8992.35 | C30: LED Lighting option covering Red, Green, Blue, InfraRed and Far-Red
A31: CHEMIMOD-RIR | B31: =INDEX('Raw Data for ERP Import'!$B:$B,MATCH(A31,'Raw Data for ERP Import'!$A:$A,0)) -> 4303.8 | C31: chemiPRO Red and IR Module
A32: CHEMIMOD-GBIRFR | B32: 7074.6 | C32: chemiPRO Green, Blue, Infrared and Far Red Lighting Module
A33: CHEMIMOD-GBFR | B33: 4917.9 | C33: chemiPRO Green, Blue and Far Red Lighting Module
A34: CHEMIMOD-IRFR | B34: 4144.4 | C34: chemiPRO Infrared and Far Red Lighting Module
A35: CHEMIMOD-RGBUV | B35: 7074.6 | C35: chemiPRO Red , Green, blue and UV Lighting Module
A36: CHEMIMOD-BRIRFR | B36: 6867.9 | C36: chemiPRO Blue, Red, Far Red and IR Lighting Module
A37: CHEMIMOD-UP-GB | B37: =INDEX('Raw Data for ERP Import'!$B:$B,MATCH(A37,'Raw Data for ERP Import'!$A:$A,0)) -> 3034.8 | C37: LED Lighting upgrade RIR to RGBIR
A38: CHEMIMOD-UP-IR | B38: =INDEX('Raw Data for ERP Import'!$B:$B,MATCH(A38,'Raw Data for ERP Import'!$A:$A,0)) -> 2326.9025 | C38: LED Lighting upgrade RGB to RGBIR
A39: CHEMIMOD-UP-FR | B39: 2922.4 | C39: LED Lighting upgrade Far Red
A40: CHEMIMOD-UP-UV | B40: 990.6 | C40: LED Lighting upgrade RGB or RIR to RGBUV/RIRUV
A41: CS-NFS | B41: =INDEX('Raw Data for ERP Import'!$B:$B,MATCH(A41,'Raw Data for ERP Import'!$A:$A,0)) -> 28.89 | C41: Neutral field screens for UV neutral fielding (1 blue, 1 frosted).
A42: CS-NFS-SET | B42: =INDEX('Raw Data for ERP Import'!$B:$B,MATCH(A42,'Raw Data for ERP Import'!$A:$A,0)) -> 446.832 | C42: Neutral field screen & neutral density filter.
A43: CSL-PRINTUSB | C43: Mitsubishi Digital Thermal Printer | E43: Discontinued
...

Sheet chemiPRO XL
D2: chemiPRO XL Chemiluminescence Imaging System
D3: The chemiPRO is our complete solution for chemiluminescence and fluorescent western blot imaging. Featuring a highly sensitive cooled CCD Camera with high quantam efficiency, for detection of picogram level proteins, this system can image both conventional ECL style chemiluminscence blots and fluorescently tagged proteins of antibodies with the optional fluorescence module. chemiPRO XL features enhanced sensitivity and resolution cameras of 6 or 9 megapixels as well as a motorised stage for zoom.
A5: Complete Systems | B5: Include Darkroom and camera as standard. All systems include aquistion and analsys software license free.
A6: Code | B6: 2025 Price | C6: Description
A7: CHEMIPRO-XL6-E | B7: =INDEX('Raw Data for ERP Import'!$B:$B,MATCH(A7,'Raw Data for ERP Import'!$A:$A,0)) -> 27060.27 | C7: chemiPRO XL6 Imaging System without UVT, 230V, 50Hz
A8: CHEMIPRO-XL6-E60 | B8: =INDEX('Raw Data for ERP Import'!$B:$B,MATCH(A8,'Raw Data for ERP Import'!$A:$A,0)) -> 27060.27 | C8: chemiPRO XL6 Imaging System without UVT, 230V, 60Hz
A9: CHEMIPRO-XL9-E | B9: =INDEX('Raw Data for ERP Import'!$B:$B,MATCH(A9,'Raw Data for ERP Import'!$A:$A,0)) -> 29056.659 | C9: chemiPRO XL9 Imaging System without UVT, 230V, 50Hz
A10: CHEMIPRO-XL9-E60 | B10: =INDEX('Raw Data for ERP Import'!$B:$B,MATCH(A10,'Raw Data for ERP Import'!$A:$A,0)) -> 29056.659 | C10: chemiPRO XL9 Imaging System without UVT, 230V, 60Hz
A12: Options
A13: Code | C13: Description
A14: CS-2020M-E | B14: =INDEX('Raw Data for ERP Import'!$B:$B,MATCH(A14,'Raw Data for ERP Import'!$A:$A,0)) -> 853.15781 | C14: Transilluminator (20x20cm; 302nm) 230V, 50Hz + runners | D14: Other Voltages are available
A15: CS-2530M-E | B15: =INDEX('Raw Data for ERP Import'!$B:$B,MATCH(A15,'Raw Data for ERP Import'!$A:$A,0)) -> 1509.1414 | C15: Transilluminator (25x30cm; 302nm) 230V, 50Hz + runners | D15: Other Voltages are available
A16: CS-2020LM-E | B16: =INDEX('Raw Data for ERP Import'!$B:$B,MATCH(A16,'Raw Data for ERP Import'!$A:$A,0)) -> 1183.0455 | C16: Transilluminator (20x20cm; 302/365nm) 230V, 50Hz + runners | D16: Other Voltages are available
A17: CS-2530LM-E | B17: =INDEX('Raw Data for ERP Import'!$B:$B,MATCH(A17,'Raw Data for ERP Import'!$A:$A,0)) -> 1677.877 | C17: Transilluminator (25x30cm; 302/365nm) 230V, 50Hz + runners | D17: Other Voltages are available
A18: GX-VP | B18: =INDEX('Raw Data for ERP Import'!$B:$B,MATCH(A18,'Raw Data for ERP Import'!$A:$A,0)) -> 131.75156 | C18: Viewing platform
A19: CS-ULTRA-BRIGHT-LED | B19: =INDEX('Raw Data for ERP Import'!$B:$B,MATCH(A19,'Raw Data for ERP Import'!$A:$A,0)) -> 1132.659 | C19: Blue LED Transilluminator, Viewing area 20x16cm + sliding tray
A20: CS-FSG-72 | B20: =INDEX('Raw Data for ERP Import'!$B:$B,MATCH(A20,'Raw Data for ERP Import'!$A:$A,0)) -> 128.92163 | C20: Safe stain filter to work with blue light converter (gelPRO/chemiPRO)
A21: CS-BLC | B21: =INDEX('Raw Data for ERP Import'!$B:$B,MATCH(A21,'Raw Data for ERP Import'!$A:$A,0)) -> 476.00563 | C21: UV to Blue light converter, Size 25x30cm suitable for DNA safe dyes
A22: CS-WLC | B22: =INDEX('Raw Data for ERP Import'!$B:$B,MATCH(A22,'Raw Data for ERP Import'!$A:$A,0)) -> 155.12683 | C22: Viisible light converter, Size 30.5x33cm
A23: CS-EPIUV | B23: =INDEX('Raw Data for ERP Import'!$B:$B,MATCH(A23,'Raw Data for ERP Import'!$A:$A,0)) -> 1300.5154 | C23: 2 x UV module – with 302nm tubes
A24: CHEMIMOD-RGB | B24: =INDEX('Raw Data for ERP Import'!$B:$B,MATCH(A24,'Raw Data for ERP Import'!$A:$A,0)) -> 5107.05 | C24: HILED Lighting option covering Red, Green and Blue
A25: CHEMIMOD-RGBIR | B25: =INDEX('Raw Data for ERP Import'!$B:$B,MATCH(A25,'Raw Data for ERP Import'!$A:$A,0)) -> 6609.1292 | C25: HILED Lighting option covering Red, Green, Blue and InfraRed
A26: CHEMIMOD-RGBIRFR | B26: =INDEX('Raw Data for ERP Import'!$B:$B,MATCH(A26,'Raw Data for ERP Import'!$A:$A,0)) -> 8992.35 | C26: LED Lighting option covering Red, Green, Blue, InfraRed and Far-Red
A27: CHEMIMOD-RIR | B27: =INDEX('Raw Data for ERP Import'!$B:$B,MATCH(A27,'Raw Data for ERP Import'!$A:$A,0)) -> 4303.8 | C27: HILED Lighting option covering Red and InfraRed
A28: CHEMIMOD-GBIRFR | B28: 7074.6 | C28: chemiPRO Green, Blue, Infrared and Far Red Lighting Module
A29: CHEMIMOD-GBFR | B29: 4917.9 | C29: chemiPRO Green, Blue and Far Red Lighting Module
A30: CHEMIMOD-IRFR | B30: 4144.4 | C30: chemiPRO Infrared and Far Red Lighting Module
A31: CHEMIMOD-RGBUV | B31: 7074.6 | C31: chemiPRO Red , Green, blue and UV Lighting Module
A32: CHEMIMOD-BRIRFR | B32: 6867.9 | C32: chemiPRO Blue, Red, Far Red and IR Lighting Module
A33: CHEMIMOD-UP-GB | B33: =INDEX('Raw Data for ERP Import'!$B:$B,MATCH(A33,'Raw Data for ERP Import'!$A:$A,0)) -> 3034.8 | C33: HILED Lighting upgrade RIR to RGBIR
A34: CHEMIMOD-UP-IR | B34: =INDEX('Raw Data for ERP Import'!$B:$B,MATCH(A34,'Raw Data for ERP Import'!$A:$A,0)) -> 2326.9025 | C34: HILED Lighting upgrade RGB to RGBIR
A35: CHEMIMOD-UP-FR | B35: 2922.4 | C35: LED Lighting upgrade Far Red
A36: CHEMIMOD-UP-UV | B36: 990.6 | C36: LED Lighting upgrade RGB or RIR to RGBUV/RIRUV
A37: CS-FSP | B37: =INDEX('Raw Data for ERP Import'!$B:$B,MATCH(A37,'Raw Data for ERP Import'!$A:$A,0)) -> 1096.513 | C37: Short pass [516 - 600nm] (SW06)
A38: CS-FIR | B38: =INDEX('Raw Data for ERP Import'!$B:$B,MATCH(A38,'Raw Data for ERP Import'!$A:$A,0)) -> 1776.4642 | C38: Filter for Licor multiplexing 800nm
A39: CS-FBL | B39: =INDEX('Raw Data for ERP Import'!$B:$B,MATCH(A39,'Raw Data for ERP Import'!$A:$A,0)) -> 1296.7999 | C39: 525nm Filter (range 516-539m)
A40: CS-FGL | B40: =INDEX('Raw Data for ERP Import'!$B:$B,MATCH(A40,'Raw Data for ERP Import'!$A:$A,0)) -> 1738.546 | C40: 605nm Filter for Multiplexing (range 594-610nm)
A41: CS-FRL | B41: =INDEX('Raw Data for ERP Import'!$B:$B,MATCH(A41,'Raw Data for ERP Import'!$A:$A,0)) -> 1738.546 | C41: 705nm Filter for Multiplexing (range 700-720nm)
A42: CS-FFR | B42: 1861.6 | C42: 700nm Filter for Far Red multiplexing (range 698-764nm)
A43: CS-CYLIGHT | B43: =INDEX('Raw Data for ERP Import'!$B:$B,MATCH(A43,'Raw Data for ERP Import'!$A:$A,0)) -> 15682.686 | C43: Dyversity CY dye edge lighting module (28x21cm).
...

Sheet chemiPRO XS
D2: chemiPRO XS Chemiluminescence Imaging System
D3: The chemiPRO is our complete solution for chemiluminescence and fluorescent western blot imaging. Featuring a highly sensitive cooled CCD Camera with high quantam efficiency, for detection of picogram level proteins, this system can image both conventional ECL style chemiluminscence blots and fluorescently tagged proteins of antibodies with the optional fluorescence module. chemiPRO XS features enhanced sensitivity and resolution cameras of 6 or 9 megapixels as well as a reduced footprint for space saving.
A5: Complete Systems | B5: Include Darkroom and camera as standard. All systems include aquistion and analsys software license free.
A6: Code | B6: 2025 Price | C6: Description
A7: CHEMIPRO-XS6-E | B7: =INDEX('Raw Data for ERP Import'!$B:$B,MATCH(A7,'Raw Data for ERP Import'!$A:$A,0)) -> 21503.369 | C7: chemiPRO XS6 Imaging System without UVT, 230V, 50Hz
A8: CHEMIPRO-XS6-E60 | B8: =INDEX('Raw Data for ERP Import'!$B:$B,MATCH(A8,'Raw Data for ERP Import'!$A:$A,0)) -> 21503.369 | C8: chemiPRO XS6 Imaging System without UVT, 230V, 60Hz
A9: CHEMIPRO-XS6-US | B9: =INDEX('Raw Data for ERP Import'!$B:$B,MATCH(A9,'Raw Data for ERP Import'!$A:$A,0)) -> 21503.369 | C9: chemiPRO XS6 Imaging System without UVT, 115V, 60Hz
A10: CHEMIPRO-XS6-JA | B10: =INDEX('Raw Data for ERP Import'!$B:$B,MATCH(A10,'Raw Data for ERP Import'!$A:$A,0)) -> 21503.369 | C10: chemiPRO XS6 Imaging System without UVT, 100V, 50/60Hz
A11: CHEMIPRO-XS9-E | B11: =INDEX('Raw Data for ERP Import'!$B:$B,MATCH(A11,'Raw Data for ERP Import'!$A:$A,0)) -> 22489.23 | C11: chemiPRO XS9 Imaging System without UVT, 230V, 50Hz
A12: CHEMIPRO-XS9-E60 | B12: =INDEX('Raw Data for ERP Import'!$B:$B,MATCH(A12,'Raw Data for ERP Import'!$A:$A,0)) -> 22489.23 | C12: chemiPRO XS9 Imaging System without UVT, 230V, 60Hz
A13: CHEMIPRO-XS9-US | B13: =INDEX('Raw Data for ERP Import'!$B:$B,MATCH(A13,'Raw Data for ERP Import'!$A:$A,0)) -> 22489.23 | C13: chemiPRO XS9 Imaging System without UVT, 115V, 60Hz
A14: CHEMIPRO-XS9-JA | B14: =INDEX('Raw Data for ERP Import'!$B:$B,MATCH(A14,'Raw Data for ERP Import'!$A:$A,0)) -> 22489.23 | C14: chemiPRO XS9 Imaging System without UVT, 100V, 50/60Hz
A16: Options
A17: Code | C17: Description
A18: CS-2020M-E | B18: =INDEX('Raw Data for ERP Import'!$B:$B,MATCH(A18,'Raw Data for ERP Import'!$A:$A,0)) -> 853.15781 | C18: Transilluminator (20 x 20cm; 302nm) 230V, 50Hz with runners
A19: CHEMIMOD-XS-RGB | B19: =INDEX('Raw Data for ERP Import'!$B:$B,MATCH(A19,'Raw Data for ERP Import'!$A:$A,0)) -> 5107.05 | C19: LED Lighting option covering Red, Green and Blue
A20: CHEMIMOD-XS-RGBIR | B20: =INDEX('Raw Data for ERP Import'!$B:$B,MATCH(A20,'Raw Data for ERP Import'!$A:$A,0)) -> 7628.8402 | C20: LED Lighting option covering Red, Green, Blue and InfraRed
A21: CHEMIMOD-XS-RIR | B21: =INDEX('Raw Data for ERP Import'!$B:$B,MATCH(A21,'Raw Data for ERP Import'!$A:$A,0)) -> 4303.8 | C21: LED Lighting option covering Red and InfraRed
A22: CHEMIMOD-XS-RGBUV | B22: 7074.6 | C22: LED Lighting option covering Red, Green, Blue and UV
A23: CHEMIMOD-XS-GBIRFR | B23: 7074.6 | C23: LED Lighting option covering Green, Blue, Infrared and Far Red
A24: CHEMIMOD-XS-GBFR | B24: 4917.9 | C24: LED Lighting option covering Green, Blue and Far Red
A25: CHEMIMOD-XS-IRFR | B25: 4144.4 | C25: LED Lighting option covering Infrared and Far Red
A26: CHEMIMOD-XS-UP-GB | B26: =INDEX('Raw Data for ERP Import'!$B:$B,MATCH(A26,'Raw Data for ERP Import'!$A:$A,0)) -> 3151.4123 | C26: LED Lighting upgrade RIR to RGBIR
A27: CHEMIMOD-XS-UP-IR | B27: =INDEX('Raw Data for ERP Import'!$B:$B,MATCH(A27,'Raw Data for ERP Import'!$A:$A,0)) -> 2326.9025 | C27: LED Lighting upgrade RGB to RGBIR
A28: CHEMIMOD-XS-UV | B28: 990.6 | C28: LED Lighting upgrade RGB or RIR to RGBUV/RIRUV
A29: CHEMIMOD-XS-FR | B29: 2255.5 | C29: LED Lighting upgrade Far Red
A30: CS-FSP | B30: =INDEX('Raw Data for ERP Import'!$B:$B,MATCH(A30,'Raw Data for ERP Import'!$A:$A,0)) -> 1096.513 | C30: Short pass [516 - 600nm] (SW06)
A31: CS-FIR | B31: =INDEX('Raw Data for ERP Import'!$B:$B,MATCH(A31,'Raw Data for ERP Import'!$A:$A,0)) -> 1776.4642 | C31: Filter for Licor multiplexing 800nm
A32: CS-FBL | B32: =INDEX('Raw Data for ERP Import'!$B:$B,MATCH(A32,'Raw Data for ERP Import'!$A:$A,0)) -> 1296.7999 | C32: 525nm Filter (range 516-539m)
A33: CS-FGL | B33: =INDEX('Raw Data for ERP Import'!$B:$B,MATCH(A33,'Raw Data for ERP Import'!$A:$A,0)) -> 1738.546 | C33: 605nm Filter for Multiplexing (range 594-610nm)
A34: CS-FRL | B34: =INDEX('Raw Data for ERP Import'!$B:$B,MATCH(A34,'Raw Data for ERP Import'!$A:$A,0)) -> 1738.546 | C34: 705nm Filter for Multiplexing (range 700-720nm)
A35: CS-FFR | B35: 1861.6 | C35: 700nm Filter for Far Red multiplexing (range 698-764nm)
A36: CHEMIXS-VP | B36: =INDEX('Raw Data for ERP Import'!$B:$B,MATCH(A36,'Raw Data for ERP Import'!$A:$A,0)) -> 131.75156 | C36: Viewing platform for blots
A37: WLC-3023 | B37: =INDEX('Raw Data for ERP Import'!$B:$B,MATCH(A37,'Raw Data for ERP Import'!$A:$A,0)) -> 155.12683 | C37: Visible light converter
A38: CS-ULTRA-SLIM-LED | B38: =INDEX('Raw Data for ERP Import'!$B:$B,MATCH(A38,'Raw Data for ERP Import'!$A:$A,0)) -> 811.7596 | C38: Blue slimline LED transilluminator, 10x12cm + sliding tray
A39: CS-FSG-72 | B39: =INDEX('Raw Data for ERP Import'!$B:$B,MATCH(A39,'Raw Data for ERP Import'!$A:$A,0)) -> 128.92163 | C39: Safe stain filter to work with blue light converter (gelPRO/chemiPRO)
A40: BLC-2126 | B40: =INDEX('Raw Data for ERP Import'!$B:$B,MATCH(A40,'Raw Data for ERP Import'!$A:$A,0)) -> 454.75538 | C40: UV to Blue Light converter, Size 21x26cm, suitable for safe dyes
A41: CS-XS-NFS | B41: =INDEX('Raw Data for ERP Import'!$B:$B,MATCH(A41,'Raw Data for ERP Import'!$A:$A,0)) -> 28.89 | C41: Neutral field screens for UV neutral fielding (1 blue, 1 frosted).
A42: CSL-PRINTUSB | C42: Mitsubishi Digital Thermal Printer | E42: Discontinued
A43: CSL-PRINTER | B43: 1235 | C43: Sony Digital Thermal Printer
...

Sheet Additional Filters
A1: Code | B1: 2025 Price | C1: Description
A2: CS-FUV-GX | B2: =INDEX('Raw Data for ERP Import'!$B:$B,MATCH(A2,'Raw Data for ERP Import'!$A:$A,0)) -> 524.88121 | C2: UV Filter (UV032) | D2: For gelPRO, Included
A3: CS-FLP-GX | B3: =INDEX('Raw Data for ERP Import'!$B:$B,MATCH(A3,'Raw Data for ERP Import'!$A:$A,0)) -> 539.75638 | C3: Long Pass [615-644nm] (LW032) | D3: For gelPRO
A4: CS-FUV-GX-CHEMI | B4: =INDEX('Raw Data for ERP Import'!$B:$B,MATCH(A4,'Raw Data for ERP Import'!$A:$A,0)) -> 1096.513 | C4: UV Filter (UV06) | D4: For chemiPRO Chemi systems, included
A5: CS-FLP-GX-CHEMI | B5: =INDEX('Raw Data for ERP Import'!$B:$B,MATCH(A5,'Raw Data for ERP Import'!$A:$A,0)) -> 1096.513 | C5: Long Pass [611 - 641nm] (LW06) | D5: For chemiPRO Chemi systems
A6: CS-FFRLP-GX | B6: =INDEX('Raw Data for ERP Import'!$B:$B,MATCH(A6,'Raw Data for ERP Import'!$A:$A,0)) -> 1829.6466 | C6: FRLP Filter 670-780nm | D6: For chemiPRO Chemi systems
A7: CS-FIR-GX | B7: =INDEX('Raw Data for ERP Import'!$B:$B,MATCH(A7,'Raw Data for ERP Import'!$A:$A,0)) -> 1402.5166 | C7: IR Filter. | D7: For chemiPRO Chemi systems
A8: CS-F565-GX | B8: =INDEX('Raw Data for ERP Import'!$B:$B,MATCH(A8,'Raw Data for ERP Import'!$A:$A,0)) -> 1496.0177 | C8: 565nm Filter (range 556-579nm) | D8: For chemiPRO Chemi systems
A9: CS-F585-GX | B9: =INDEX('Raw Data for ERP Import'!$B:$B,MATCH(A9,'Raw Data for ERP Import'!$A:$A,0)) -> 1496.0177 | C9: 585nm Filter (range 580-590nm) | D9: For chemiPRO Chemi systems
A10: CS-F605-GX | B10: =INDEX('Raw Data for ERP Import'!$B:$B,MATCH(A10,'Raw Data for ERP Import'!$A:$A,0)) -> 1496.0177 | C10: 605nm Filter (range 590-607nm) | D10: For chemiPRO Chemi systems
A11: CS-F625-GX | B11: =INDEX('Raw Data for ERP Import'!$B:$B,MATCH(A11,'Raw Data for ERP Import'!$A:$A,0)) -> 1496.0177 | C11: 625nm Filter (range 600-640nm) | D11: For chemiPRO Chemi systems
A12: CS-F655-GX | B12: =INDEX('Raw Data for ERP Import'!$B:$B,MATCH(A12,'Raw Data for ERP Import'!$A:$A,0)) -> 1496.0177 | C12: 655nm Filter (range 633-675nm) | D12: For chemiPRO Chemi systems
A13: CS-F705-GX | B13: =INDEX('Raw Data for ERP Import'!$B:$B,MATCH(A13,'Raw Data for ERP Import'!$A:$A,0)) -> 1496.0177 | C13: 705nm Filter (range 697-717nm) | D13: For chemiPRO Chemi systems
A14: CS-FUV-58 | B14: =INDEX('Raw Data for ERP Import'!$B:$B,MATCH(A14,'Raw Data for ERP Import'!$A:$A,0)) -> 367.62935 | C14: UV filter (UV032)
A15: CS-FLP-58 | B15: =INDEX('Raw Data for ERP Import'!$B:$B,MATCH(A15,'Raw Data for ERP Import'!$A:$A,0)) -> 520.63116 | C15: Long pass filter (LW032)
A16: CS-FUV06-58 | B16: =INDEX('Raw Data for ERP Import'!$B:$B,MATCH(A16,'Raw Data for ERP Import'!$A:$A,0)) -> 597.13206 | C16: UV Filter (UV06) for stain free imaging [572-625nm]
A17: CS-FSG-72 | B17: =INDEX('Raw Data for ERP Import'!$B:$B,MATCH(A17,'Raw Data for ERP Import'!$A:$A,0)) -> 128.92163 | C17: Safe stain filter to work with blue light converter (gelPRO/chemiPRO)
A18: CS-FSG-58 | B18: =INDEX('Raw Data for ERP Import'!$B:$B,MATCH(A18,'Raw Data for ERP Import'!$A:$A,0)) -> 103.1373 | C18: Safe stain filter to work with blue light converter (gelLITE/gelONE)

Sheet Workflow Packages
A1: Workflow Packages
A2: SKU | B2: Description | C2: 2025 Price
A3: WESTERNFLOWLITE | B3: Complete Western Blotting workflow solution with chemiLITE | C3: =INDEX('Raw Data for ERP Import'!$B:$B,MATCH(A3,'Raw Data for ERP Import'!$A:$A,0)) -> 12359.255
A4: WESTERNFLOWXS | B4: Complete Mini Blotting workflow solution with chemiPRO XS | C4: =INDEX('Raw Data for ERP Import'!$B:$B,MATCH(A4,'Raw Data for ERP Import'!$A:$A,0)) -> 23367.21
A5: WESTERNFLOWXLMINI | B5: Complete Mini Blotting workflow solution with chemiPRO XL | C5: =INDEX('Raw Data for ERP Import'!$B:$B,MATCH(A5,'Raw Data for ERP Import'!$A:$A,0)) -> 29654.139
A6: WESTERNFLOWXLMAXI | B6: Complete Maxi Blotting workflow solution with chemiPRO XL | C6: =INDEX('Raw Data for ERP Import'!$B:$B,MATCH(A6,'Raw Data for ERP Import'!$A:$A,0)) -> 30013.583
A7: WESTERNFLOWPROMINI | B7: Complete Mini Blotting workflow solution with chemiPRO | C7: =INDEX('Raw Data for ERP Import'!$B:$B,MATCH(A7,'Raw Data for ERP Import'!$A:$A,0)) -> 16993.712
A8: WESTERNFLOWPROMAXI | B8: Complete Maxi Blotting workflow solution with chemiPRO | C8: =INDEX('Raw Data for ERP Import'!$B:$B,MATCH(A8,'Raw Data for ERP Import'!$A:$A,0)) -> 17353.156
A9: WESTERNFLOWXSRGB | B9: Complete Mini RGB Blotting package with chemiPRO XS6 220V | C9: =INDEX('Raw Data for ERP Import'!$B:$B,MATCH(A9,'Raw Data for ERP Import'!$A:$A,0)) -> 32466.057
A10: WESTERNFLOWXLMINIRGB | B10: Complete Mini RGB Blotting package with chemiPRO XL | C10: =INDEX('Raw Data for ERP Import'!$B:$B,MATCH(A10,'Raw Data for ERP Import'!$A:$A,0)) -> 38553.428
A11: WESTERNFLOWXLMAXIRGB | B11: Complete Maxi RGB Blotting package with chemiPRO XL | C11: =INDEX('Raw Data for ERP Import'!$B:$B,MATCH(A11,'Raw Data for ERP Import'!$A:$A,0)) -> 38912.872
A12: WESTERNFLOWPROMINIRGB | B12: Complete Mini RGB Blotting package with chemiPRO | C12: =INDEX('Raw Data for ERP Import'!$B:$B,MATCH(A12,'Raw Data for ERP Import'!$A:$A,0)) -> 26729.651
A13: WESTERNFLOWPROMAXIRGB | B13: Complete Maxi RGB Blotting package with chemiPRO | C13: =INDEX('Raw Data for ERP Import'!$B:$B,MATCH(A13,'Raw Data for ERP Import'!$A:$A,0)) -> 26957.124
A14: GELONEPACK | B14: Complete 15 x 15 cm agarose gel documentation kit with gelONE | C14: =INDEX('Raw Data for ERP Import'!$B:$B,MATCH(A14,'Raw Data for ERP Import'!$A:$A,0)) -> 0
... A16: GELPROPACK | B16: Complete Maxi agarose gel documentation kit with gelPRO | C16: =INDEX('Raw Data for ERP Import'!$B:$B,MATCH(A16,'Raw Data for ERP Import'!$A:$A,0)) -> 11015.118

Sheet Raw Data for ERP Import
A1: Code | B1: 2025 Price | C1: Description
A2: BLC-2126 | B2: 454.75538 | C2: UV to Blue Light converter, Size 21x26cm, suitable for safe dyes
A3: ChemiLITE | B3: 10775.466 | C3: Dedicated High Performance, compact Chemi System
A4: CHEMIMOD-RGB | B4: 5107.05 | C4: chemiPRO RGB Lighting Module
A5: CHEMIMOD-RGBIR | B5: 6609.1292 | C5: chemiPRO RGB & IR Lighitng Module
A6: CHEMIMOD-RIR | B6: 4303.8 | C6: chemiPRO Red and IR Module
A7: CHEMIMOD-UP-GB | B7: 3034.8 | C7: LED Lighting upgrade RIR to RGBIR
A8: CHEMIMOD-UP-IR | B8: 2326.9025 | C8: LED Lighting upgrade RGB to RGBIR
A9: CHEMIMOD-XS-RGB | B9: 5107.05 | C9: LED Lighting option covering Red, Green and Blue
A10: CHEMIMOD-XS-RGBIR | B10: 7628.8402 | C10: LED Lighting option covering Red, Green, Blue and InfraRed
A11: CHEMIMOD-RGBIRFR | B11: 8992.35 | C11: LED Lighting option covering Red, Green, Blue, InfraRed and Far-Red
A12: CHEMIMOD-XS-RIR | B12: 4303.8 | C12: LED Lighting option covering Red and InfraRed
A13: CHEMIMOD-XS-UP-GB | B13: 3151.4123 | C13: LED Lighting upgrade RIR to RGBIR
... A73: CS-GLOSSP | B73: 27.625327 | C73: Thermal paper, Glossy, 1 roll
A74: CSL-PRINTUSB | C74: Mitsubishi Digital Thermal Printer | D74: Discontinued
A75: CSL-PRINTER | B75: 1235 | C75: Sony Digital Thermal Printer
A76: CS-UPP-100HD | B76: 17.55 | C76: Matt Paper roll for use with Sony printer Pk1
A77: CS-UPP-110HG | B77: 17.55 | C77: Gloss Paper roll for use with Sont printer Pk1
A78: CS-MATTP | B78: 27.625327 | C78: Thermal paper, Matt, 1 roll
A79: CS-NFS | B79: 28.89 | C79: Neutral field screens for UV neutral fielding (1 blue, 1 frosted).
A80: CS-NFS-SET | B80: 446.832 | C80: Neutral field screen & neutral density filter.
A81: CS-T8-254 | B81: 27.05157 | C81: Short wave tube, 8W, 254nm
A82: CS-T8-302 | B82: 33.816588 | C82: Medium wave, 8W, 302nm
A83: CS-T8-365 | B83: 27.593451 | C83: Longwave 8W, 365nm
A84: CS-ULTRA-BRIGHT-LED | B84: 1132.659 | C84: Blue LED Transilluminator, Viewing area 20x16cm + sliding tray
A85: CS-ULTRA-SLIM-LED | B85: 811.7596 | C85: Blue slimline LED transilluminator, 10x12cm + sliding tray
A86: CS-WLC | B86: 155.12683 | C86: Viisible light converter, Size 30.5x33cm
... A106: GELONEXE -BASE | B106: 7020 | C106: gelONE-XE BASE ONLY 230V, 50Hz, Europe
A107: GELONE-A | C107: Discontinued
A108: GELONE-BASE | C108: Discontinued
A109: GELONE-E | C109: Discontinued
A110: GELONE-E60 | C110: Discontinued
A111: GELONE-NETUSB | B111: 210.37749 | C111: Network dongle
A112: GELONEPACK | C112: Discontinued
A113: GELONE-PLUS | C113: Discontinued
A114: GELONE-PLUS-E60 | C114: Discontinued
A115: GELONE-PLUS-A | C115: Discontinued
A116: gelPRO-302C | B116: 9372.0576 | C116: gelPRO with Large 302nm 115V 60Hz (Canada) UVT
A117: gelPRO-302E | B117: 9372.0576 | C117: gelPRO with Large 302nm 230V 50Hz (Europe) UVT
A118: gelPRO-302J | B118: 9372.0576 | C118: gelPRO with Large 302nm 100V 50/60Hz (Japan) UVT
...
